INFO: Starting training:
        Epochs:          5
        Batch size:      1
        Learning rate:   1e-05
        Training size:   90
        Validation size: 10
        Checkpoints:     True
        Device:          cpu
        Images scaling:  0.5
        Mixed Precision: False
Epoch 1/5:   0%|                                                                                          | 0/90 [00:01<?, ?img/s]
Traceback (most recent call last):
  File "train.py", line 188, in <module>
    train_net(net=net,
  File "train.py", line 79, in train_net
    for batch in train_loader:
  File "/Users/cameronhildebrandt/opt/anaconda3/lib/python3.8/site-packages/torch/utils/data/dataloader.py", line 681, in __next__
    data = self._next_data()
  File "/Users/cameronhildebrandt/opt/anaconda3/lib/python3.8/site-packages/torch/utils/data/dataloader.py", line 1376, in _next_data
    return self._process_data(data)
  File "/Users/cameronhildebrandt/opt/anaconda3/lib/python3.8/site-packages/torch/utils/data/dataloader.py", line 1402, in _process_data
    data.reraise()
  File "/Users/cameronhildebrandt/opt/anaconda3/lib/python3.8/site-packages/torch/_utils.py", line 461, in reraise
    raise exception
AssertionError: Caught AssertionError in DataLoader worker process 0.
Original Traceback (most recent call last):
  File "/Users/cameronhildebrandt/opt/anaconda3/lib/python3.8/site-packages/torch/utils/data/_utils/worker.py", line 302, in _worker_loop
    data = fetcher.fetch(index)
  File "/Users/cameronhildebrandt/opt/anaconda3/lib/python3.8/site-packages/torch/utils/data/_utils/fetch.py", line 49, in fetch
    data = [self.dataset[idx] for idx in possibly_batched_index]
  File "/Users/cameronhildebrandt/opt/anaconda3/lib/python3.8/site-packages/torch/utils/data/_utils/fetch.py", line 49, in <listcomp>
    data = [self.dataset[idx] for idx in possibly_batched_index]
  File "/Users/cameronhildebrandt/opt/anaconda3/lib/python3.8/site-packages/torch/utils/data/dataset.py", line 290, in __getitem__
    return self.dataset[self.indices[idx]]
  File "/Users/cameronhildebrandt/Desktop/Pytorch-UNet/utils/data_loading.py", line 62, in __getitem__
    assert len(mask_file) == 1, f'Either no mask or multiple masks found for the ID {name}: {mask_file}'
AssertionError: Either no mask or multiple masks found for the ID 00001: []